func error(reason) ->
    throw (:error, {reason=reason}) end

x =
try
    print("IN TRY")
    error(:TestError)
catch e
    print("CATCH")
    print(e)
finally
    print("Finally")
    42
end

print(x)

error(:BadError)


